# promise基础题
## 第一题
```js
const promise1 = new Promise((resolve, reject) => {
  console.log('promise1')
  resolve('resolve1')
})
const promise2 = promise1.then(res => {
  console.log(res)
})
console.log('1', promise1);
console.log('2', promise2);

// 'promise1'
// '1' Promise{<resolved>: 'resolve1'}
// '2' Promise{<pending>}
// 'resolve1'
```
从上至下，先遇到new Promise，执行该构造函数中的代码promise1
碰到resolve函数, 将promise1的状态改变为resolved, 并将结果保存下来
碰到promise1.then这个微任务，将它放入微任务队列
promise2是一个新的状态为pending的Promise
执行同步代码1， 同时打印出promise1的状态是resolved
执行同步代码2，同时打印出promise2的状态是pending
宏任务执行完毕，查找微任务队列，发现promise1.then这个微任务且状态为resolved，执行它

## 第二题
```js
const fn = () => (new Promise((resolve, reject) => {
  console.log(1);
  resolve('success')
}))
fn().then(res => {
  console.log(res)
})
console.log('start')

// 1
// 'start'
// 'success'
```

# promise结合setTimeout
## 第一题
```js
const promise = new Promise((resolve, reject) => {
  console.log(1);
  setTimeout(() => {
    console.log("timerStart");
    resolve("success");
    console.log("timerEnd");
  }, 0);
  console.log(2);
});
promise.then((res) => {
  console.log(res);
});
console.log(4);

// 1
// 2
// 4
// timerStart
// timerEnd
// success
```
从上至下，先遇到new Promise，执行该构造函数中的代码1
然后碰到了定时器，将这个定时器中的函数放到下一个宏任务的延迟队列中等待执行
执行同步代码2
跳出promise函数，遇到promise.then，但其状态还是为pending，这里理解为先不执行
执行同步代码4
一轮循环过后，进入第二次宏任务，发现延迟队列中有setTimeout定时器，执行它
首先执行timerStart，然后遇到了resolve，将promise的状态改为resolved且保存结果并将之前的promise.then推入微任务队列
继续执行同步代码timerEnd
宏任务全部执行完毕，查找微任务队列，发现promise.then这个微任务，执行它。

## 第二题
```js
const promise1 = new Promise((resolve, reject) => {
  setTimeout(() => {
    resolve('success')
  }, 1000)
})
const promise2 = promise1.then(() => {
  throw new Error('error!!!')
})
console.log('promise1', promise1)
console.log('promise2', promise2)
setTimeout(() => {
  console.log('promise1', promise1)
  console.log('promise2', promise2)
}, 2000)

// 'promise1' Promise{<pending>}
// 'promise2' Promise{<pending>}
// test5.html:102 Uncaught (in promise) Error: error!!! at test.html:102
// 'promise1' Promise{<resolved>: "success"}
// 'promise2' Promise{<rejected>: Error: error!!!}

```
从上至下，先执行第一个new Promise中的函数，碰到setTimeout将它加入下一个宏任务列表
跳出new Promise，碰到promise1.then这个微任务，但其状态还是为pending，这里理解为先不执行
promise2是一个新的状态为pending的Promise
执行同步代码console.log('promise1')，且打印出的promise1的状态为pending
执行同步代码console.log('promise2')，且打印出的promise2的状态为pending
碰到第二个定时器，将其放入下一个宏任务列表
第一轮宏任务执行结束，并且没有微任务需要执行，因此执行第二轮宏任务
先执行第一个定时器里的内容，将promise1的状态改为resolved且保存结果并将之前的promise1.then推入微任务队列
该定时器中没有其它的同步代码可执行，因此执行本轮的微任务队列，也就是promise1.then，它抛出了一个错误，且将promise2的状态设置为了rejected
第一个定时器执行完毕，开始执行第二个定时器中的内容
打印出'promise1'，且此时promise1的状态为resolved
打印出'promise2'，且此时promise2的状态为rejected


## 第三题
```js
Promise.resolve().then(() => {
  console.log('promise1');
  const timer2 = setTimeout(() => {
    console.log('timer2')
  }, 0)
});
const timer1 = setTimeout(() => {
  console.log('timer1')
  Promise.resolve().then(() => {
    console.log('promise2')
  })
}, 0)
console.log('start');

// start
// promise1
// timer1
// promise2
// timer2
```

刚开始整个脚本作为第一次宏任务来执行，我们将它标记为宏1，从上至下执行
遇到Promise.resolve().then这个微任务，将then中的内容加入第一次的微任务队列标记为微1
遇到定时器timer1，将它加入下一次宏任务的延迟列表，标记为宏2，等待执行(先不管里面是什么内容)
执行宏1中的同步代码start
第一次宏任务(宏1)执行完毕，检查第一次的微任务队列(微1)，发现有一个promise.then这个微任务需要执行
执行打印出微1中同步代码promise1，然后发现定时器timer2，将它加入宏2的后面，标记为宏3
第一次微任务队列(微1)执行完毕，执行第二次宏任务(宏2)，首先执行同步代码timer1
然后遇到了promise2这个微任务，将它加入此次循环的微任务队列，标记为微2
宏2中没有同步代码可执行了，查找本次循环的微任务队列(微2)，发现了promise2，执行它
第二轮执行完毕，执行宏3，打印出timer2

# promise的then、catch、finally
## 第一题
```js
const promise = new Promise((resolve, reject) => {
  reject("error");
  resolve("success2");
});
promise
.then(res => {
    console.log("then1: ", res);
  }).then(res => {
    console.log("then2: ", res);
  }).catch(err => {
    console.log("catch: ", err);
  }).then(res => {
    console.log("then3: ", res);
  })

// catch: error
// then3: undefined
```
resolve和reject只有第一次有效，多次调用没有任何效果
catch不管被连接到哪里，都能捕获上层未捕捉过的错误
至于then3也会被执行，那是因为catch()也会返回一个Promise，且由于这个Promise没有返回值，所以打印出来的是undefined

## 第二题
```js
Promise.resolve().then(() => {
  return new Error('error!!!')
}).then(res => {
  console.log("then: ", res)
}).catch(err => {
  console.log("catch: ", err)
})

// then："Error: error!!!"
```
返回任意一个非 promise 的值都会被包裹成 promise 对象，因此这里的return new Error('error!!!')也被包裹成了return Promise.resolve(new Error('error!!!'))。

## 第三题
```js
Promise.resolve(1)
  .then(2)
  .then(Promise.resolve(3))
  .then(console.log)
//   1
```
.then 或者 .catch 的参数期望是函数，传入非函数则会发生值透传。
第一个then和第二个then中传入的都不是函数，一个是数字类型，一个是对象类型，因此发生了透传，将resolve(1) 的值直接传到最后一个then里。

# promise all race
## 第一题
```js
function runAsync (x) {
  const p = new Promise(r => setTimeout(() => r(x, console.log(x)), 1000))
  return p
}
function runReject (x) {
  const p = new Promise((res, rej) => setTimeout(() => rej(`Error: ${x}`, console.log(x)), 1000 * x))
  return p
}
Promise.all([runAsync(1), runReject(4), runAsync(3), runReject(2)])
  .then(res => console.log(res))
  .catch(err => console.log(err))
```
catch会捕获最先的那个异常

# async/await
跟着await后面的语句相当于放到了new Promise中，下一行及之后的语句相当于放在Promise.then中
## 第一题
```js
async function async1() {
  console.log("async1 start");
  await async2();
  console.log("async1 end");
  setTimeout(() => {
    console.log('timer1')
  }, 0)
}
async function async2() {
  setTimeout(() => {
    console.log('timer2')
  }, 0)
  console.log("async2");
}
async1();
setTimeout(() => {
  console.log('timer3')
}, 0)
console.log("start")
```

## 第二题
```js
async function async1 () {
  console.log('async1 start');
  await new Promise(resolve => {
    console.log('promise1')
  })
  console.log('async1 success');
  return 'async1 end'
}
console.log('srcipt start')
async1().then(res => console.log(res))
console.log('srcipt end')

```
在async1中await后面的Promise是没有返回值的，也就是它的状态始终是pending状态，因此相当于一直在await，await，await却始终没有响应...
所以在await之后的内容是不会执行的，也包括async1后面的 .then。

如果在async函数中抛出了错误，则终止错误结果，不会继续向下执行。
如果想要使得错误的地方不影响async函数后续的执行的话，可以使用try catch

## 综合题
```js
const first = () => (new Promise((resolve, reject) => {
    console.log(3);
    let p = new Promise((resolve, reject) => {
        console.log(7);
        setTimeout(() => {
            console.log(5);
            resolve(6);
            console.log(p)
        }, 0)
        resolve(1);
    });
    resolve(2);
    p.then((arg) => {
        console.log(arg);
    });
}));
first().then((arg) => {
    console.log(arg);
});
console.log(4);

```

```js
// 代码梳理一下
new Promise((resolve, reject) => {
    console.log(3);
    new Promise((resolve, reject) => {
        console.log(7);
        setTimeout(() => {
            console.log(5);
            resolve(6);
            console.log(p)
        }, 0)
        resolve(1);
    }).then((arg) => {
        console.log(arg);
    });
    resolve(2);
}).then((arg) => {
    console.log(arg);
});
console.log(4);
// 3
// 7
// 4
// 1
// 2
// 5
// Promise{<resolved>: 1}
```
第一段代码定义的是一个函数，所以我们得看看它是在哪执行的，发现它在4之前，所以可以来看看first函数里面的内容了。(这一步有点类似于题目1.5)
函数first返回的是一个new Promise()，因此先执行里面的同步代码3
接着又遇到了一个new Promise()，直接执行里面的同步代码7
执行完7之后，在p中，遇到了一个定时器，先将它放到下一个宏任务队列里不管它，接着向下走
碰到了resolve(1)，这里就把p的状态改为了resolved，且返回值为1，不过这里也先不执行
跳出p，碰到了resolve(2)，这里的resolve(2)，表示的是把first函数返回的那个Promise的状态改了，也先不管它。
然后碰到了p.then，将它加入本次循环的微任务列表，等待执行
跳出first函数，遇到了first().then()，将它加入本次循环的微任务列表(p.then的后面执行)
然后执行同步代码4
本轮的同步代码全部执行完毕，查找微任务列表，发现p.then和first().then()，依次执行，打印出1和2
本轮任务执行完毕了，发现还有一个定时器没有跑完，接着执行这个定时器里的内容，执行同步代码5
然后又遇到了一个resolve(6)，它是放在p里的，但是p的状态在之前已经发生过改变了，因此这里就不会再改变，也就是说resolve(6)相当于没任何用处，因此打印出来的p为Promise{<resolved>: 1}。

## 第二题
```js
const async1 = async () => {
  console.log('async1');
  setTimeout(() => {
    console.log('timer1')
  }, 2000)
  await new Promise(resolve => {
    console.log('promise1')
  })
  console.log('async1 end')
  return 'async1 success'
} 
console.log('script start');
async1().then(res => console.log(res));
console.log('script end');
Promise.resolve(1)
  .then(2)
  .then(Promise.resolve(3))
  .catch(4)
  .then(res => console.log(res))
setTimeout(() => {
  console.log('timer2')
}, 1000)
// 'script start'
// 'async1'
// 'promise1'
// 'script end'
// 1
// 'timer2'
// 'timer1'
```
async函数中await的new Promise要是没有返回值的话则不执行后面的内容(类似题5.5)
.then函数中的参数期待的是函数，如果不是函数的话会发生透传(类似题3.8 )
注意定时器的延迟时间

## 第三题
```js
const p1 = new Promise((resolve) => {
  setTimeout(() => {
    resolve('resolve3');
    console.log('timer1')
  }, 0)
  resolve('resovle1');
  resolve('resolve2');
}).then(res => {
  console.log(res)
  setTimeout(() => {
    console.log(p1)
  }, 1000)
}).finally(res => {
  console.log('finally', res)
})

// 'resolve1'
// 'finally' undefined
// 'timer1'
// Promise{<resolved>: undefined}
```

Promise的状态一旦改变就无法改变
finally不管Promise的状态是resolved还是rejected都会执行，且它的回调函数是接收不到Promise的结果的，所以finally()中的res是一个迷惑项(类似3.10)。
最后一个定时器打印出的p1其实是.finally的返回值，我们知道.finally的返回值如果在没有抛出错误的情况下默认会是上一个Promise的返回值(3.10中也有提到), 而这道题中.finally上一个Promise是.then()，但是这个.then()并没有返回值，所以p1打印出来的Promise的值会是undefined，如果你在定时器的下面加上一个return 1，则值就会变成1
